Workbook

Sheet Nifty 50_data
A1: Date | B1: Open | C1: High | D1: Low | E1: Close | F1: Daily Return %
A2: 36528 | B2: 1482.15 | C2: 1592.9 | D2: 1482.15 | E2: 1592.2 | F2: =((E3-E2)/2)*100 -> 2325
A3: 36529 | B3: 1594.4 | C3: 1641.95 | D3: 1594.4 | E3: 1638.7 | F3: =((E4-E3)/2)*100 -> -2145
A4: 36530 | B4: 1634.55 | C4: 1635.5 | D4: 1555.05 | E4: 1595.8 | F4: =((E5-E4)/2)*100 -> 1090
A5: 36531 | B5: 1595.8 | C5: 1639 | D5: 1595.8 | E5: 1617.6 | F5: =((E6-E5)/2)*100 -> -215
A6: 36532 | B6: 1616.6 | C6: 1628.25 | D6: 1597.2 | E6: 1613.3 | F6: =((E7-E6)/2)*100 -> 980
A7: 36535 | B7: 1615.65 | C7: 1662.1 | D7: 1614.95 | E7: 1632.9 | F7: =((E8-E7)/2)*100 -> -3020
A8: 36536 | B8: 1633.25 | C8: 1639.9 | D8: 1548.25 | E8: 1572.5 | F8: =((E9-E8)/2)*100 -> 2615
A9: 36537 | B9: 1572.3 | C9: 1631.55 | D9: 1571.7 | E9: 1624.8 | F9: =((E10-E9)/2)*100 -> -170
A10: 36538 | B10: 1627.85 | C10: 1671.15 | D10: 1613.65 | E10: 1621.4 | F10: =((E11-E10)/2)*100 -> 65
A11: 36539 | B11: 1622.15 | C11: 1627.4 | D11: 1591.4 | E11: 1622.7 | F11: =((E12-E11)/2)*100 -> -555
A12: 36542 | B12: 1623.5 | C12: 1668.45 | D12: 1604.65 | E12: 1611.6 | F12: =((E13-E12)/2)*100 -> -245
A13: 36543 | B13: 1611.65 | C13: 1615.15 | D13: 1587.85 | E13: 1606.7 | F13: =((E14-E13)/2)*100 -> 1405
... A5646: 44813 | B5646: 17923.35 | C5646: 17925.95 | D5646: 17786 | E5646: 17833.35 | F5646: =((E5647-E5646)/2)*100 -> -891667.5

Sheet Bank
A1: Date | B1: Open | C1: High | D1: Low | E1: Close | F1: Daily Return%
A2: 38512 | B2: 3659.8 | C2: 3664.45 | D2: 3609.75 | E2: 3636.5 | F2: =((E3-E2)/E2)*100 -> -1.1824557
A3: 38513 | B3: 3640.05 | C3: 3665.8 | D3: 3585.8 | E3: 3593.5 | F3: =((E4-E3)/E3)*100 -> 1.3747043
A4: 38516 | B4: 3593.9 | C4: 3648.4 | D4: 3556.7 | E4: 3642.9 | F4: =((E5-E4)/E4)*100 -> 1.2874358
A5: 38517 | B5: 3649.05 | C5: 3696.35 | D5: 3637.7 | E5: 3689.8 | F5: =((E6-E5)/E5)*100 -> -0.16261044
A6: 38518 | B6: 3700.8 | C6: 3703.75 | D6: 3662.85 | E6: 3683.8 | F6: =((E7-E6)/E6)*100 -> -1.7644823
A7: 38519 | B7: 3684.4 | C7: 3685.75 | D7: 3607.2 | E7: 3618.8 | F7: =((E8-E7)/E7)*100 -> -0.6355698
A8: 38520 | B8: 3625.1 | C8: 3627.45 | D8: 3581.8 | E8: 3595.8 | F8: =((E9-E8)/E8)*100 -> -1.7826353
A9: 38523 | B9: 3600.9 | C9: 3627.35 | D9: 3518.95 | E9: 3531.7 | F9: =((E10-E9)/E9)*100 -> 1.2968259
A10: 38524 | B10: 3529.05 | C10: 3587.1 | D10: 3529.05 | E10: 3577.5 | F10: =((E11-E10)/E10)*100 -> -0.46401118
A11: 38525 | B11: 3578.65 | C11: 3614.95 | D11: 3546.95 | E11: 3560.9 | F11: =((E12-E11)/E11)*100 -> 1.3816732
A12: 38526 | B12: 3561.25 | C12: 3614.9 | D12: 3537.8 | E12: 3610.1 | F12: =((E13-E12)/E12)*100 -> -0.3047007
A13: 38527 | B13: 3612 | C13: 3627.85 | D13: 3571.9 | E13: 3599.1 | F13: =((E14-E13)/E13)*100 -> -0.072240282
... A4279: 44813 | B4279: 40520.75 | C4279: 40685.95 | D4279: 40280.3 | E4279: 40415.7 | F4279: =((E4280-E4279)/E4279)*100 -> -100

Sheet Energy Data
A1: Date | B1: Open | C1: High | D1: Low | E1: Close | F1: Daily Return
A2: 36892 | B2: 26688.85 | C2: 27197.95 | D2: 26627.1 | E2: 27163.95 | F2: =((E3-E2)/E2)*100 -> -1.8487738
A3: 36893 | B3: 26807.25 | C3: 26861.75 | D3: 26583.35 | E3: 26661.75 | F3: =((E4-E3)/E3)*100 -> 0.011252075
A4: 36894 | B4: 26772.05 | C4: 26825.6 | D4: 26526.95 | E4: 26664.75 | F4: =((E5-E4)/E4)*100 -> 0.24039228
A5: 36895 | B5: 26407.6 | C5: 26762.95 | D5: 26334.4 | E5: 26728.85 | F5: =((E6-E5)/E5)*100 -> -1.1605438
A6: 36896 | B6: 26842.1 | C6: 26902.55 | D6: 26272.9 | E6: 26418.65 | F6: =((E7-E6)/E6)*100 -> 1.4576824
A7: 36899 | B7: 27115.6 | C7: 27173.25 | D7: 26512.05 | E7: 26803.75 | F7: =((E8-E7)/E7)*100 -> 0.92710908
A8: 36900 | B8: 27121.6 | C8: 27283.6 | D8: 26780.1 | E8: 27052.25 | F8: =((E9-E8)/E8)*100 -> -0.050827565
A9: 36901 | B9: 26770.25 | C9: 27088.1 | D9: 26683.85 | E9: 27038.5 | F9: =((E10-E9)/E9)*100 -> -1.0801265
A10: 36902 | B10: 26101.3 | C10: 26825.1 | D10: 26045.15 | E10: 26746.45 | F10: =((E11-E10)/E10)*100 -> -2.7220435
A11: 36903 | B11: 25715.3 | C11: 26052.6 | D11: 25658.5 | E11: 26018.4 | F11: =((E12-E11)/E11)*100 -> -1.7789334
A12: 36906 | B12: 25422.1 | C12: 25595.65 | D12: 25302.5 | E12: 25555.55 | F12: =((E13-E12)/E12)*100 -> -1.083522
A13: 36907 | B13: 25255.9 | C13: 25328.65 | D13: 25170 | E13: 25278.65 | F13: =((E14-E13)/E13)*100 -> -0.02096631
... A2861: 41073 | B2861: 8688.4 | C2861: 8852.75 | D2861: 8639 | E2861: 8788 | F2861: =((E2862-E2861)/E2861)*100 -> -100

Sheet FMCG
A1: Date | B1: Open | C1: High | D1: Low | E1: Close | F1: Daily Return %
A2: 40574 | B2: 8707.95 | C2: 8709.95 | D2: 8500.65 | E2: 8595.7 | F2: =((E3-E2)/E2)*100 -> -1.7008504
A3: 40575 | B3: 8625.6 | C3: 8665.5 | D3: 8352.75 | E3: 8449.5 | F3: =((E4-E3)/E3)*100 -> -0.11243269
A4: 40576 | B4: 8491.25 | C4: 8555.25 | D4: 8411.95 | E4: 8440 | F4: =((E5-E4)/E4)*100 -> 0.60781991
A5: 40577 | B5: 8411.1 | C5: 8551.15 | D5: 8405.25 | E5: 8491.3 | F5: =((E6-E5)/E5)*100 -> -3.0772673
A6: 40578 | B6: 8495.85 | C6: 8524 | D6: 8188.75 | E6: 8230 | F6: =((E7-E6)/E6)*100 -> 1.2320778
A7: 40581 | B7: 8332.6 | C7: 8396 | D7: 8240.15 | E7: 8331.4 | F7: =((E8-E7)/E7)*100 -> -0.8473966
A8: 40582 | B8: 8356.05 | C8: 8378.7 | D8: 8239.8 | E8: 8260.8 | F8: =((E9-E8)/E8)*100 -> -0.9647976
A9: 40583 | B9: 8248.4 | C9: 8263.2 | D9: 8111.9 | E9: 8181.1 | F9: =((E10-E9)/E9)*100 -> 0.16623681
A10: 40584 | B10: 8167.65 | C10: 8284.2 | D10: 8162.9 | E10: 8194.7 | F10: =((E11-E10)/E10)*100 -> -0.097624074
A11: 40585 | B11: 8214.95 | C11: 8230.2 | D11: 8118.55 | E11: 8186.7 | F11: =((E12-E11)/E11)*100 -> 2.5211624
A12: 40588 | B12: 8191.35 | C12: 8443.4 | D12: 8191.35 | E12: 8393.1 | F12: =((E13-E12)/E12)*100 -> -0.20016442
A13: 40589 | B13: 8430.1 | C13: 8440.4 | D13: 8328.75 | E13: 8376.3 | F13: =((E14-E13)/E13)*100 -> 0.43455941
... A2861: 44785 | B2861: 42536.2 | C2861: 42547.25 | D2861: 42126.85 | E2861: 42457.3 | F2861: =((E2862-E2861)/E2861)*100 -> -100

Sheet AUTO
A1: Date | B1: Open | C1: High | D1: Low | E1: Close | F1: Daily return%
A2: 40819 | B2: 12938 | C2: 12953.15 | D2: 12847.45 | E2: 12923.75 | F2: =((E3-E2)/E2)*100 -> -0.0015475384
A3: 40820 | B3: 13080.2 | C3: 13097.35 | D3: 12859.9 | E3: 12923.55 | F3: =((E4-E3)/E3)*100 -> 0.21743252
A4: 40821 | B4: 12959.05 | C4: 12992.7 | D4: 12868.5 | E4: 12951.65 | F4: =((E5-E4)/E4)*100 -> -0.18298827
A5: 40823 | B5: 12821.55 | C5: 12977.8 | D5: 12816.4 | E5: 12927.95 | F5: =((E6-E5)/E5)*100 -> -0.95606805
A6: 40826 | B6: 12977.8 | C6: 12981.1 | D6: 12782.8 | E6: 12804.35 | F6: =((E7-E6)/E6)*100 -> 1.1039217
A7: 40827 | B7: 13006.7 | C7: 13024.3 | D7: 12754.25 | E7: 12945.7 | F7: =((E8-E7)/E7)*100 -> -0.20315626
A8: 40828 | B8: 13036.8 | C8: 13036.8 | D8: 12767.75 | E8: 12919.4 | F8: =((E9-E8)/E8)*100 -> 0.80692602
A9: 40829 | B9: 12921.95 | C9: 13048.55 | D9: 12817.05 | E9: 13023.65 | F9: =((E10-E9)/E9)*100 -> -0.53748373
A10: 40830 | B10: 12645.65 | C10: 12974.35 | D10: 12627.95 | E10: 12953.65 | F10: =((E11-E10)/E10)*100 -> -3.168605
A11: 40833 | B11: 12482.55 | C11: 12687.6 | D11: 12474.15 | E11: 12543.2 | F11: =((E12-E11)/E11)*100 -> -1.2716053
A12: 40834 | B12: 12357.55 | C12: 12417.6 | D12: 12238.7 | E12: 12383.7 | F12: =((E13-E12)/E12)*100 -> -0.46310876
A13: 40835 | B13: 12289 | C13: 12342.55 | D13: 12204.65 | E13: 12326.35 | F13: =((E14-E13)/E13)*100 -> -0.40441818
... A2693: 44785 | B2693: 3530.5 | C2693: 3562.6 | D2693: 3512.45 | E2693: 3534.6 | F2693: =((E2694-E2693)/E2693)*100 -> -100

Sheet Master
A2: Date | B2: index | C2: Open | D2: High | E2: Low | F2: Close | G2: Daily Return %
A3: 36528 | B3: "NIFTY50" | C3: 1482.15 | D3: 1592.9 | E3: 1482.15 | F3: 1592.2 | G3: =((F4-F3)/F3)*100 -> 2.9204874
A4: 36529 | B4: "NIFTY50" | C4: 1594.4 | D4: 1641.95 | E4: 1594.4 | F4: 1638.7 | G4: =((F5-F4)/F4)*100 -> -2.6179288
A5: 36530 | B5: "NIFTY50" | C5: 1634.55 | D5: 1635.5 | E5: 1555.05 | F5: 1595.8 | G5: =((F6-F5)/F5)*100 -> 1.366086
A6: 36531 | B6: "NIFTY50" | C6: 1595.8 | D6: 1639 | E6: 1595.8 | F6: 1617.6 | G6: =((F7-F6)/F6)*100 -> -0.26582591
A7: 36532 | B7: "NIFTY50" | C7: 1616.6 | D7: 1628.25 | E7: 1597.2 | F7: 1613.3 | G7: =((F8-F7)/F7)*100 -> 1.2149011
A8: 36535 | B8: "NIFTY50" | C8: 1615.65 | D8: 1662.1 | E8: 1614.95 | F8: 1632.9 | G8: =((F9-F8)/F8)*100 -> -3.6989405
A9: 36536 | B9: "NIFTY50" | C9: 1633.25 | D9: 1639.9 | E9: 1548.25 | F9: 1572.5 | G9: =((F10-F9)/F9)*100 -> 3.3259141
A10: 36537 | B10: "NIFTY50" | C10: 1572.3 | D10: 1631.55 | E10: 1571.7 | F10: 1624.8 | G10: =((F11-F10)/F10)*100 -> -0.20925652
A11: 36538 | B11: "NIFTY50" | C11: 1627.85 | D11: 1671.15 | E11: 1613.65 | F11: 1621.4 | G11: =((F12-F11)/F11)*100 -> 0.080177624
A12: 36539 | B12: "NIFTY50" | C12: 1622.15 | D12: 1627.4 | E12: 1591.4 | F12: 1622.7 | G12: =((F13-F12)/F12)*100 -> -0.68404511
A13: 36542 | B13: "NIFTY50" | C13: 1623.5 | D13: 1668.45 | E13: 1604.65 | F13: 1611.6 | G13: =((F14-F13)/F13)*100 -> -0.30404567
A14: 36543 | B14: "NIFTY50" | C14: 1611.65 | D14: 1615.15 | E14: 1587.85 | F14: 1606.7 | G14: =((F15-F14)/F14)*100 -> 1.7489264
... A5646: 44812 | B5646: "NIFTY50" | C5646: 17748.15 | D5646: 17807.65 | E5646: 17691.95 | F5646: 17798.75 | G5646: =((F5647-F5646)/F5646)*100 -> 0.19439567
A5647: 44813 | B5647: "NIFTY50" | C5647: 17923.35 | D5647: 17925.95 | E5647: 17786 | F5647: 17833.35 | G5647: 0
A5649: 38512 | B5649: "BANK" | C5649: 3659.8 | D5649: 3664.45 | E5649: 3609.75 | F5649: 3636.5 | G5649: =((F5650-F5649)/F5649)*100 -> -1.1824557
A5650: 38513 | B5650: "BANK" | C5650: 3640.05 | D5650: 3665.8 | E5650: 3585.8 | F5650: 3593.5 | G5650: =((F5651-F5650)/F5650)*100 -> 1.3747043
A5651: 38516 | B5651: "BANK" | C5651: 3593.9 | D5651: 3648.4 | E5651: 3556.7 | F5651: 3642.9 | G5651: =((F5652-F5651)/F5651)*100 -> 1.2874358
A5652: 38517 | B5652: "BANK" | C5652: 3649.05 | D5652: 3696.35 | E5652: 3637.7 | F5652: 3689.8 | G5652: =((F5653-F5652)/F5652)*100 -> -0.16261044
A5653: 38518 | B5653: "BANK" | C5653: 3700.8 | D5653: 3703.75 | E5653: 3662.85 | F5653: 3683.8 | G5653: =((F5654-F5653)/F5653)*100 -> -1.7644823
A5654: 38519 | B5654: "BANK" | C5654: 3684.4 | D5654: 3685.75 | E5654: 3607.2 | F5654: 3618.8 | G5654: =((F5655-F5654)/F5654)*100 -> -0.6355698
A5655: 38520 | B5655: "BANK" | C5655: 3625.1 | D5655: 3627.45 | E5655: 3581.8 | F5655: 3595.8 | G5655: =((F5656-F5655)/F5655)*100 -> -1.7826353
A5656: 38523 | B5656: "BANK" | C5656: 3600.9 | D5656: 3627.35 | E5656: 3518.95 | F5656: 3531.7 | G5656: =((F5657-F5656)/F5656)*100 -> 1.2968259
A5657: 38524 | B5657: "BANK" | C5657: 3529.05 | D5657: 3587.1 | E5657: 3529.05 | F5657: 3577.5 | G5657: =((F5658-F5657)/F5657)*100 -> -0.46401118
A5658: 38525 | B5658: "BANK" | C5658: 3578.65 | D5658: 3614.95 | E5658: 3546.95 | F5658: 3560.9 | G5658: =((F5659-F5658)/F5658)*100 -> 1.3816732
A5659: 38526 | B5659: "BANK" | C5659: 3561.25 | D5659: 3614.9 | E5659: 3537.8 | F5659: 3610.1 | G5659: =((F5660-F5659)/F5659)*100 -> -0.3047007
A5660: 38527 | B5660: "BANK" | C5660: 3612 | D5660: 3627.85 | E5660: 3571.9 | F5660: 3599.1 | G5660: =((F5661-F5660)/F5660)*100 -> -0.072240282
... A9925: 44812 | B9925: "BANK" | C9925: 39763.9 | D9925: 40265.75 | E9925: 39706.4 | F9925: 40208.95 | G9925: =((F9926-F9925)/F9925)*100 -> 0.51418901
A9926: 44813 | B9926: "BANK" | C9926: 40520.75 | D9926: 40685.95 | E9926: 40280.3 | F9926: 40415.7 | G9926: 0
A9928: 36892 | B9928: "ENERGY DATA" | C9928: 26688.85 | D9928: 27197.95 | E9928: 26627.1 | F9928: 27163.95 | G9928: =((F9929-F9928)/F9928)*100 -> -1.8487738
A9929: 36893 | B9929: "ENERGY DATA" | C9929: 26807.25 | D9929: 26861.75 | E9929: 26583.35 | F9929: 26661.75 | G9929: =((F9930-F9929)/F9929)*100 -> 0.011252075
A9930: 36894 | B9930: "ENERGY DATA" | C9930: 26772.05 | D9930: 26825.6 | E9930: 26526.95 | F9930: 26664.75 | G9930: =((F9931-F9930)/F9930)*100 -> 0.24039228
A9931: 36895 | B9931: "ENERGY DATA" | C9931: 26407.6 | D9931: 26762.95 | E9931: 26334.4 | F9931: 26728.85 | G9931: =((F9932-F9931)/F9931)*100 -> -1.1605438
A9932: 36896 | B9932: "ENERGY DATA" | C9932: 26842.1 | D9932: 26902.55 | E9932: 26272.9 | F9932: 26418.65 | G9932: =((F9933-F9932)/F9932)*100 -> 1.4576824
A9933: 36899 | B9933: "ENERGY DATA" | C9933: 27115.6 | D9933: 27173.25 | E9933: 26512.05 | F9933: 26803.75 | G9933: =((F9934-F9933)/F9933)*100 -> 0.92710908
A9934: 36900 | B9934: "ENERGY DATA" | C9934: 27121.6 | D9934: 27283.6 | E9934: 26780.1 | F9934: 27052.25 | G9934: =((F9935-F9934)/F9934)*100 -> -0.050827565
A9935: 36901 | B9935: "ENERGY DATA" | C9935: 26770.25 | D9935: 27088.1 | E9935: 26683.85 | F9935: 27038.5 | G9935: =((F9936-F9935)/F9935)*100 -> -1.0801265
A9936: 36902 | B9936: "ENERGY DATA" | C9936: 26101.3 | D9936: 26825.1 | E9936: 26045.15 | F9936: 26746.45 | G9936: =((F9937-F9936)/F9936)*100 -> -2.7220435
A9937: 36903 | B9937: "ENERGY DATA" | C9937: 25715.3 | D9937: 26052.6 | E9937: 25658.5 | F9937: 26018.4 | G9937: =((F9938-F9937)/F9937)*100 -> -1.7789334
A9938: 36906 | B9938: "ENERGY DATA" | C9938: 25422.1 | D9938: 25595.65 | E9938: 25302.5 | F9938: 25555.55 | G9938: =((F9939-F9938)/F9938)*100 -> -1.083522
...

Sheet Summary 
G4: SUMMARY OF STOCK ANALYSIS PROJECT
F6: Metric | G6: NIFTY 50 | H6: BANK | I6: ENERGY | J6: FMCG | K6: AUTO
F7: Max close price | G7: =MAX(Master!F2:F5647) -> 18477.05 | H7: =MAX(Master!F5649:F9926) -> 41238.3 | I7: =MAX(Master!F9928:F12787) -> 29046.1 | J7: =MAX(Master!F12789:F15648) -> 42978.5 | K7: =MAX(Master!F15650:F18341) -> 13023.65
F8: Min close price | G8: =MIN(Master!F3:F5647) -> 854.2 | H8: =MIN(Master!F5649:F9926) -> 3339.7 | I8: =MIN(Master!F9928:F12787) -> 6875.8 | J8: =MIN(Master!F12789:F15648) -> 8157.4 | K8: =MIN(Master!F15650:F18341) -> 3304.8
F9: Avg Daily return | G9: =AVERAGE(Master!G3:G5647) -> 0.053048112 | H9: =AVERAGE(Master!G5649:G9926) -> 0.073442956 | I9: =AVERAGE(Master!G9928:G12787) -> -0.030550799 | J9: =AVERAGE(Master!G12789:G15648) -> 0.061882695 | K9: =AVERAGE(Master!G15650:G18341) -> -0.038394761
F10: Total Trading days | G10: =COUNTA(Master!A3:A5647) -> 5645 | H10: =COUNTA(Master!A5649:A9926) -> 4278 | I10: =COUNTA(Master!A9928:A12787) -> 2860 | J10: =COUNTA(Master!A12789:A15648) -> 2860 | K10: =COUNTA(Master!A15650:A18341) -> 2692
F11: Volatility(Std dev) | G11: =STDEV(Master!G3:G5645) -> 1.4294966 | H11: =STDEV(Master!G5649:G9926) -> 1.8512236 | I11: =STDEV(Master!G9928:G12787) -> 1.3376054 | J11: =STDEV(Master!G12789:G15648) -> 1.0966335 | K11: =STDEV(Master!G15650:G18341) -> 1.4004247
